Workbook

Sheet README
A1: Faceprint Atlas: facial privacy protection literature workbook
A2: 225 entries from 1999 to 2026, densest coverage from 2018. Last updated September 2026. Interactive version: https://atulkr05.github.io/atlas.html
A4: How to use this workbook
A5: "All papers" holds every entry with the full record. Year tabs (Before 2018, then 2018 onward) and family tabs hold the same columns filtered. "Summary" counts entries by year and family with live COUNTIFS formulas over "All papers". "Attacks vs defenses" pairs defense papers with the papers that tested them. "Datasets index" and "Models index" count how often common datasets and backbones appear.
A7: Families
A8: Blur, pixelation & obfuscation | B8: Blur, pixelate, scramble, warp, average k faces, or capture less in the first place. The oldest family, and the one most often shown not to stop machines. Examples: k-Same, Street View blur, privacy optics.
A9: Differential privacy | B9: Calibrated noise with a formal privacy budget, applied to pixels, features, templates, gradients or generative models. Examples: DP-SGD, IdentityDP, DP diffusion.
A10: De-identification (generative) | B10: Synthesise a new face that keeps pose, expression and attributes but not identity. GANs from 2017, diffusion from 2023, often reversible with a key. Examples: DeepPrivacy, CIAGAN, RiDDLE, G2Face.
A11: Adversarial privacy | B11: Perturb photos, makeup or accessories so recognisers fail while humans see the same face. Cloaks poison training; masks and makeup evade matching. Examples: Fawkes, LowKey, CLIP2Protect, DiffAM.
A12: Unlearnable images & anti-customisation | B12: Make images useless as training data: unlearnable examples against classifiers, and anti-DreamBooth protections against personalised diffusion models. Examples: Unlearnable Examples, Anti-DreamBooth, PhotoGuard.
A13: Identity protection: templates & encrypted matching | B13: Protect the faceprint itself: cancelable transforms, fuzzy vaults, homomorphic encryption, and recognition on representations that hide the image. Examples: PolyProtect, HERS, IronMask, PartialFace.
A14: Soft-biometric privacy | B14: Keep a face usable for matching while suppressing what else it reveals: gender, age, ethnicity, health. Examples: PrivacyNet, SensitiveNets, PASS.
A15: Training-data privacy & synthetic data | B15: Train recognisers without hoarding faces: federated learning, synthetic identities, consented datasets, instance encoding. Examples: FedFace, DCFace, DigiFace-1M.
A16: Machine unlearning & auditing | B16: Remove a person from a trained model, erase an identity from a generator, or prove that a face was used in training. Examples: SalUn, GUIDE, Face-Auditor.
A17: Attacks & evaluations | B17: Papers that invert templates, defeat obfuscation, break cloaks and unlearnable examples, or measure whether anonymisation really removes identity. Examples: NbNet, Data Poisoning Won't Save You, GrIDPure.
A18: Surveys, audits & society | B18: Surveys that organise the field, audits that exposed bias, investigations and standards that changed what is deployed. Examples: Meden et al. 2021, Gender Shades, Exposing.ai.
A20: Caveats
B21: Curated catalogue, not a systematic review. Venues and years were checked against arXiv metadata and proceedings; preprints may since have been published. Findings are summaries, so read the paper before citing a number. Code links point only to repositories that could be confirmed.

Sheet All papers
A1: All papers
A2: Every entry, newest first. Use the filter arrows on the header row.
A4: # | B4: ID | C4: Paper title | D4: Authors | E4: Year | F4: Venue | G4: Venue type | H4: Family | I4: Chart group | J4: Datasets | K4: Models / backbones | L4: Approach | M4: Key findings | N4: Threat model / protects against | O4: Utility preserved | P4: Limitations & known attacks | Q4: Tags | R4: Code available | S4: GitHub / code link | T4: Paper link | U4: Google Scholar
A5: 1 | B5: hahn2026 | C5: A Deeper Dive into the Irreversibility of PolyProtect: Making Protected Face Templates Harder to Invert | D5: Vedrana Krivokuća Hahn, Jérémy Maceiras, Sébastien Marcel | E5: 2026 | F5: Under review (submitted to IEEE TIFS) | G5: Preprint | H5: Attacks & evaluations | I5: Attacks & evaluations | J5: MOBIO, LFW | K5: PolyProtect templates | L5: Analyses inversion of PolyProtect templates and proposes a key-selection algorithm that raises inversion difficulty consistently across parameters. | M5: Showed prior parameter choices left some templates invertible and fixed it with principled key selection. | N5: Attacker with protected templates. | O5: Verification accuracy retained. | P5: Under review. | Q5: PolyProtect, inversion, key selection | R5: No | T5: https://arxiv.org/abs/2605.03857 | U5: Search
A6: 2 | B6: zhang2026 | C6: Adversarial Attacks for Good: A Survey of Proactive Protection across the Visual Content Lifecycle | D6: Jiaming Zhang, Boyang Chen, Zherui Li, Fuyao Zhang, Xinyu Yan, Hong Xi Tae, Wenwen He, Xuan Wang, Siqi Guo, Junhao Dong, Kun Wang, Hanxun Huang, Yige Li, Xingjun Ma, Yang Cao, Lingjuan Lyu, Wei Yang Bryan Lim | E6: 2026 | F6: arXiv preprint | G6: Preprint | H6: Surveys, audits & society | I6: Surveys & society | J6: Survey | K6: Survey | L6: Surveys the use of adversarial perturbation as protection across creation, sharing and training of visual content, including face cloaks and anti-deepfake immunisation. | M6: Frames cloaking, watermarking and immunisation as one family with shared robustness problems. | N6: Not applicable. | O6: Not applicable. | P6: Preprint. | Q6: survey, proactive protection, adversarial for good | R6: No | T6: https://arxiv.org/abs/2608.04314 | U6: Search
A7: 3 | B7: wang2026diffmi | C7: DiffMI: Breaking Face Recognition Privacy via Diffusion-Driven Training-Free Model Inversion | D7: Hanrui Wang, Shuo Wang, Chun-Shien Lu, Isao Echizen | E7: 2026 | F7: IEEE TIFS | G7: Journal | H7: Attacks & evaluations | I7: Attacks & evaluations | J7: LFW, CelebA-HQ | K7: Diffusion prior; privacy-resistant recognisers | L7: Training-free diffusion-guided inversion that reconstructs faces from embeddings without a model-specific inverter. | M7: Attack success of 84.42% to 92.87% against privacy-resistant recognisers, including some designed to resist inversion. | N7: Attacker with embeddings from protected systems. | O7: Not applicable. | P7: Compute-heavy sampling. | Q7: model inversion, diffusion, training-free | R7: No | T7: https://arxiv.org/abs/2504.18015 | U7: Search
A8: 4 | B8: wei2026toolbox | C8: FDeID-Toolbox: Face De-Identification Toolbox | D8: Hui Wei, Hao Yu, Guoying Zhao | E8: 2026 | F8: Technical report (arXiv) | G8: Preprint | H8: Surveys, audits & society | I8: Surveys & society | J8: CelebA-HQ, FFHQ, LFW | K8: Many de-identification methods (toolbox) | L8: Open toolbox implementing many de-identification methods with shared evaluation for privacy, utility and quality. | M8: A step toward the unified evaluation every survey since 2016 has asked for. | N8: Not applicable. | O8: Not applicable. | P8: Coverage still growing. | Q8: toolbox, benchmark, open source | R8: Yes | S8: https://arxiv.org/abs/2603.13121 | T8: https://arxiv.org/abs/2603.13121 | U8: Search
A9: 5 | B9: wei2026survey | C9: Face De-Identification: A Domain-Centric Survey from Capture to Processing | D9: Hui Wei, Hao Yu, Guoying Zhao | E9: 2026 | F9: arXiv preprint | G9: Preprint | H9: Surveys, audits & society | I9: Surveys & society | J9: Survey | K9: Survey | L9: Taxonomy by where the privacy transformation happens: before capture (physical), at the sensor, or after capture (digital). | M9: First survey to treat camera-side and optics-based protection alongside image processing. | N9: Not applicable. | O9: Not applicable. | P9: Preprint. | Q9: survey, physical/sensor/digital domains | R9: No | T9: https://arxiv.org/abs/2607.25926 | U9: Search
A10: 6 | B10: guo2026 | C10: FaceLinkGen: A Re-evaluation of Identity Leakage in Privacy-Preserving Face Recognition and Face Anonymization Systems Using Simple Distillation | D10: Wenqi Guo, Mohamed Shehata, Shan Du | E10: 2026 | F10: arXiv preprint | G10: Preprint | H10: Attacks & evaluations | I10: Attacks & evaluations | J10: LFW, CelebA | K10: Distilled linking model | L10: Distils a linking model that connects protected representations or anonymised faces back to identities. | M10: Recovered identities at rates above 74% across tested privacy-preserving recognition and de-identification systems. | N10: Attacker with access to protected outputs and public face data. | O10: Not applicable. | P10: Preprint; systems tested are academic. | Q10: distillation, leakage, PPFR, anonymisation | R10: No | T10: https://arxiv.org/abs/2602.02914 | U10: Search
A11: 7 | B11: wang2026flux | C11: Flux-Guard: Facial Identity Protection using Diffusion Models | D11: Jie Wang, Tao Wang, Ru Zhang, Jianyi Liu | E11: 2026 | F11: arXiv preprint | G11: Preprint | H11: Adversarial privacy | I11: Adversarial & unlearnable | J11: CelebA-HQ | K11: FLUX diffusion backbone | L11: Uses a large diffusion backbone to generate identity-protected faces guided against recognisers. | M11: Reported strong black-box protection with high image quality. | N11: Black-box recognisers. | O11: Natural appearance. | P11: Preprint; untested against adaptive attackers. | Q11: diffusion, identity protection | R11: No | T11: https://arxiv.org/abs/2606.17606 | U11: Search
A12: 8 | B12: wen2026 | C12: Image Privacy Protection: A Survey | D12: Wenying Wen, Ziye Yuan, Yushu Zhang, Tao Wang, Xiangli Xiao, Ruoyu Zhao, Yuming Fang | E12: 2026 | F12: ACM Computing Surveys | G12: Journal | H12: Surveys, audits & society | I12: Surveys & society | J12: Survey | K12: Survey | L12: Survey of image privacy protection spanning encryption, perturbation, anonymisation and access control. | M12: Places face-specific methods in the wider image privacy landscape. | N12: Not applicable. | O12: Not applicable. | P12: Breadth over depth. | Q12: survey, image privacy | R12: No | T12: https://arxiv.org/abs/2412.15228 | U12: Search
A13: 9 | B13: honig2025 | C13: Adversarial Perturbations Cannot Reliably Protect Artists From Generative AI | D13: Robert Hönig, Javier Rando, Nicholas Carlini, Florian Tramèr | E13: 2025 | F13: ICLR (arXiv 2024) | G13: ML | H13: Attacks & evaluations | I13: Attacks & evaluations | J13: Artists' styles (WikiArt and contemporary), face sets | K13: Stable Diffusion fine-tuning; Glaze, Mist, Anti-DreamBooth | L13: Shows that low-effort, off-the-shelf techniques (noisy upscaling, Gaussian noise, IMPRESS-style purification) let a forger fine-tune on protected art or photos anyway; includes a user study. | M13: Every tested protection, including Glaze, Mist and Anti-DreamBooth, was bypassed; the authors argue perturbation-based protection gives a false sense of security, echoing the Fawkes result. | N13: Images protected against fine-tuning. | O13: Not applicable. | P13: Focused on style mimicry; identity-customisation findings transfer. | Q13: Glaze, Mist, Anti-DreamBooth, robust mimicry | R13: Yes | S13: https://github.com/ethz-spylab/robust-style-mimicry | T13: https://arxiv.org/abs/2406.12027 | U13: Search
A14: 10 | B14: mustu2025 | C14: Assessing the Use of Face Swapping Methods as Face Anonymizers in Videos | D14: Mustafa İzzet Muştu, Hazım Kemal Ekenel | E14: 2025 | F14: IEEE DSP | G14: Other | H14: Attacks & evaluations | I14: Attacks & evaluations | J14: Video face benchmarks | K14: SimSwap, FaceShifter and other swappers | L14: Evaluates general-purpose face swappers as anonymisers on video for identity removal, temporal consistency and quality. | M14: Face swappers anonymised effectively but with identity leakage and consistency issues that vary by method. | N14: Not a threat paper: measures anonymisation quality. | O14: Video quality and consistency. | P14: Limited set of swappers. | Q14: evaluation, face swapping, video | R14: No | T14: https://arxiv.org/abs/2505.20985 | U14: Search
A15: 11 | B15: kwon2025 | C15: Controllable Adversarial Makeup for Privacy via Text-Guided Diffusion | D15: Youngjin Kwon, Xiao Zhang | E15: 2025 | F15: arXiv preprint | G15: Preprint | H15: Adversarial privacy | I15: Adversarial & unlearnable | J15: CelebA-HQ | K15: Stable Diffusion, CLIP | L15: MASQUE generates localised adversarial makeup from text prompts with a diffusion model, targeting dodging rather than impersonation. | M15: Robust dodging with higher perceptual fidelity and adaptability across prompts. | N15: Recognisers matching shared photos. | O15: User-chosen makeup style. | P15: Preprint. | Q15: MASQUE, diffusion, text-guided | R15: No | T15: https://arxiv.org/abs/2503.10549 | U15: Search
A16: 12 | B16: liu2023diffprotect | C16: DiffProtect: Generate Adversarial Examples with Diffusion Models for Facial Privacy Protection | D16: Jiang Liu, Chun Pong Lau, Zhongliang Guo, Yuxiang Guo, Zhaoyang Wang, Rama Chellappa | E16: 2025 | F16: Pattern Recognition (arXiv 2023) | G16: Journal | H16: Adversarial privacy | I16: Adversarial & unlearnable | J16: CelebA-HQ, LADN | K16: Diffusion autoencoder; IR152, IRSE50, FaceNet, MobileFace | L16: Uses a diffusion autoencoder to produce semantically meaningful, natural perturbations rather than pixel noise. | M16: Higher attack success and naturalness than pixel-space methods on face verification. | N16: Black-box recognisers. | O16: Natural-looking edits. | P16: Sampling cost; static protection. | Q16: diffusion, semantic perturbation | R16: Yes | S16: https://github.com/joellliu/DiffProtect | T16: https://arxiv.org/abs/2305.13625 | U16: Search
A17: 13 | B17: wang2025mm | C17: Diffusion-based Adversarial Identity Manipulation for Facial Privacy Protection | D17: Liqin Wang, Qianyue Hu, Wei Lu, Xiangyang Luo | E17: 2025 | F17: ACM Multimedia | G17: Vision | H17: Adversarial privacy | I17: Adversarial & unlearnable | J17: CelebA-HQ, LADN | K17: Diffusion sampling with identity guidance | L17: Manipulates identity-relevant components during diffusion sampling to produce protected faces. | M17: Improved transfer to black-box recognisers with natural results. | N17: Black-box recognisers. | O17: Natural appearance. | P17: Static protection. | Q17: diffusion, identity manipulation | R17: No | T17: https://arxiv.org/abs/2504.21646 | U17: Search
A18: 14 | B18: salar2025 | C18: Enhancing Facial Privacy Protection via Weakening Diffusion Purification | D18: Ali Salar, Qing Liu, Yingli Tian, Guoying Zhao | E18: 2025 | F18: CVPR | G18: Vision | H18: Adversarial privacy | I18: Adversarial & unlearnable | J18: CelebA-HQ, LADN | K18: Diffusion latent optimisation; IR152, IRSE50, FaceNet, MobileFace | L18: Learns unconditional embeddings to steer adversarial latent codes so that diffusion purification, a defense that washes out adversarial noise, no longer removes the protection; adds an identity-preserving structure. | M18: Protection survived purification-based recognisers where earlier methods failed. | N18: Recognisers that purify inputs before matching. | O18: Structural consistency with the original. | P18: Addresses one adaptive defense; others remain. | Q18: diffusion purification, adaptive attacker, latent | R18: Yes | S18: https://github.com/parham1998/Facial-Privacy-Protection | T18: https://openaccess.thecvf.com/content/CVPR2025/html/Salar_Enhancing_Facial_Privacy_Protection_via_Weakening_Diffusion_Purification_CVPR_2025_paper.html | U18: Search
A19: 15 | B19: kung2025 | C19: Face Anonymization Made Simple | D19: Han-Wei Kung, Tuomas Varanka, Sanjay Saha, Terence Sim, Nicu Sebe | E19: 2025 | F19: WACV (oral) | G19: Vision | H19: De-identification (generative) | I19: Generative de-identification | J19: CelebA-HQ, FFHQ | K19: Stable Diffusion fine-tuned for anonymisation and swapping | L19: A diffusion model trained with reconstruction losses only, needing no landmarks or masks; the same model performs anonymisation and face swapping. | M19: Preserved expression, head pose, gaze and background while changing identity; simpler pipeline than prior GAN methods. | N19: Automated face recognition on images. | O19: Expression, pose, gaze, background. | P19: Identity leakage not evaluated against adaptive attackers. | Q19: diffusion, no landmarks, face swapping | R19: Yes | S19: https://github.com/hanweikung/face_anon_simple | T19: https://arxiv.org/abs/2411.00762 | U19: Search
A20: 16 | B20: shahreza2025 | C20: Face Reconstruction from Face Embeddings using Adapter to a Face Foundation Model | D20: Hatef Otroshi Shahreza, Anjith George, Sébastien Marcel | E20: 2025 | F20: CVPR Workshops | G20: Vision | H20: Attacks & evaluations | I20: Attacks & evaluations | J20: FFHQ, LFW, MOBIO, AgeDB | K20: Arc2Face foundation model + adapters; ArcFace, AdaFace | L20: Trains a small adapter that maps embeddings from any recogniser into a face foundation model's conditioning space. | M20: High-fidelity reconstructions from many different recognisers with one foundation model and cheap adapters. | N20: Attacker with embeddings from arbitrary systems. | O20: Not applicable. | P20: Inherits the foundation model's biases. | Q20: template inversion, foundation model, adapter | R20: No | T20: https://arxiv.org/abs/2411.03960 | U20: Search
A21: 17 | B21: wang2025survey | C21: Facial Privacy in the Digital Era: A Comprehensive Survey on Methods, Evaluation, and Future Directions | D21: Miaomiao Wang et al. | E21: 2025 | F21: Computer Science Review | G21: Journal | H21: Surveys, audits & society | I21: Surveys & society | J21: Survey | K21: Survey | L21: Organises facial privacy methods into appearance-guided, identity-guided, reversible and modular paradigms with an evaluation review. | M21: Argues for unified benchmarks jointly measuring privacy, utility and visual quality. | N21: Not applicable. | O21: Not applicable. | P21: Author list abbreviated here; see DOI. | Q21: survey, four paradigms | R21: No | T21: https://doi.org/10.1016/j.cosrev.2025.100785 | U21: Search
A22: 18 | B22: song2025idprotector | C22: IDProtector: An Adversarial Noise Encoder to Protect Against ID-Preserving Image Generation | D22: Yiren Song, Pei Yang, Hai Ci, Mike Zheng Shou | E22: 2025 | F22: CVPR | G22: Vision | H22: Unlearnable images & anti-customisation | I22: Adversarial & unlearnable | J22: CelebA-HQ, FFHQ | K22: InstantID, IP-Adapter, PhotoMaker, PuLID | L22: A single feed-forward encoder adds noise that defeats encoder-based, zero-shot identity customisation (InstantID, IP-Adapter, PhotoMaker) rather than fine-tuning-based DreamBooth. | M22: One-pass protection generalised across identity-preserving generators and survived common transformations. | N22: Zero-shot face personalisation from one photo. | O22: Imperceptible noise. | P22: Targets the current family of encoders; new encoders need retraining. | Q22: encoder-based customisation, InstantID, IP-Adapter | R22: No | T22: https://arxiv.org/abs/2412.11638 | U22: Search
A23: 19 | B23: razzhigaev2025 | C23: Inverting Black-Box Face Recognition Systems via Zero-Order Optimization in Eigenface Space | D23: Anton Razzhigaev, Matvey Mikhalchuk, Klim Kireev, Igor Udovichenko, Andrey Kuznetsov, Aleksandr Petiushko | E23: 2025 | F23: arXiv preprint | G23: Preprint | H23: Attacks & evaluations | I23: Attacks & evaluations | J23: LFW, CelebA | K23: Black-box recognisers returning scores | L23: DarkerBB reconstructs a face using only similarity scores returned by a black-box system, optimising in a PCA face space with zero-order methods. | M23: Competitive reconstructions with no embedding access at all, only scores. | N23: Any system that returns similarity scores. | O23: Not applicable. | P23: Query-hungry; rate limiting is a mitigation. | Q23: black-box, similarity scores, inversion | R23: No | T23: https://arxiv.org/abs/2506.09777 | U23: Search
A24: 20 | B24: wang2025percept | C24: Make Identity Unextractable yet Perceptible: Synthesis-Based Privacy Protection for Subject Faces in Photos | D24: Tao Wang, Yushu Zhang, Xiangli Xiao, Kun Xu, Lin Yuan, Wenying Wen, Yuming Fang | E24: 2025 | F24: arXiv preprint | G24: Preprint | H24: De-identification (generative) | I24: Generative de-identification | J24: CelebA-HQ, LFW | K24: GAN synthesis with perceptual loss; ArcFace for evaluation | L24: PerceptFace synthesises a face that automated recognisers cannot match but that friends still recognise, via a perceptual similarity loss on human-sensitive regions. | M24: Reversed the usual trade-off: machine recognition removed, human recognition kept. | N24: Automated recognition of shared photos. | O24: Human recognisability and photo aesthetics. | P24: Preprint; robustness to adaptive recognisers untested. | Q24: perceptual, synthesis, human recognisability | R24: No | T24: https://arxiv.org/abs/2509.11249 | U24: Search
A25: 21 | B25: egin2025 | C25: Now You See Me, Now You Don't: A Unified Framework for Expression Consistent Anonymization in Talking Head Videos | D25: Anil Egin, Andrea Tangherloni, Antitza Dantcheva | E25: 2025 | F25: ICCV Workshops | G25: Vision | H25: De-identification (generative) | I25: Generative de-identification | J25: Talking-head video sets (VoxCeleb, HDTF) | K25: Diffusion-based anonymiser with expression consistency | L25: AnonNET anonymises talking-head video while enforcing expression consistency over time. | M25: Kept expression dynamics stable across frames while identity changed, addressing flicker in per-frame methods. | N25: Identity recognition in video. | O25: Expression and lip movement. | P25: Workshop paper; evaluation on talking-head data only. | Q25: video, expression, talking head | R25: Yes | S25: https://github.com/anilegin/AnonNET | T25: https://arxiv.org/abs/2601.11635 | U25: Search
A26: 22 | B26: wang2025protego | C26: Protego: User-Centric Pose-Invariant Privacy Protection Against Face Recognition-Induced Digital Footprint Exposure | D26: Ziling Wang, Shuya Yang, Jialin Lu, Ka-Ho Chow | E26: 2025 | F26: arXiv preprint | G26: Preprint | H26: Adversarial privacy | I26: Adversarial & unlearnable | J26: CelebA-HQ; multi-pose sets | K26: 3D-aware perturbation template | L26: A 3D-aware, pose-invariant protection template per user applied across all their photos so recognisers cannot link them. | M26: Held protection across pose variation where per-image perturbations degrade. | N26: Linking a user's photos across the web. | O26: Photos remain natural. | P26: Preprint. | Q26: pose-invariant, 3D, digital footprint | R26: No | T26: https://arxiv.org/abs/2508.02034 | U26: Search
A27: 23 | B27: labarbarie2025 | C27: Secure and Reversible Face Anonymization with Diffusion Models | D27: Pol Labarbarie, Vincent Itier, William Puech | E27: 2025 | F27: arXiv preprint | G27: Preprint | H27: De-identification (generative) | I27: Generative de-identification | J27: CelebA-HQ | K27: Key-conditioned diffusion model | L27: Key-conditioned diffusion anonymisation whose inversion recovers the original only with the secret. | M27: Reversibility with a key and resistance to recovery without it, on standard face benchmarks. | N27: Unauthorised viewers of stored images. | O27: Exact recovery for key holder. | P27: Preprint; security argued empirically. | Q27: diffusion, reversible, key | R27: No | T27: https://arxiv.org/abs/2510.01031 | U27: Search
A28: 24 | B28: wu2025 | C28: Vec2Face: Scaling Face Dataset Generation with Loosely Constrained Vectors | D28: Haiyu Wu, Jaskirat Singh, Sicong Tian, Liang Zheng, Kevin W. Bowyer | E28: 2025 | F28: ICLR | G28: ML | H28: Training-data privacy & synthetic data | I28: Training data & unlearning | J28: WebFace4M (train); LFW, CFP-FP, AgeDB, CALFW, CPLFW, Hadrian, Eclipse | K28: Feature-to-image generator; ArcFace/ViT recognisers | L28: Generates faces from sampled feature vectors with loose constraints, scaling to hundreds of thousands of synthetic identities. | M28: Larger synthetic identity counts than prior work, approaching real-data accuracy on standard benchmarks. | N28: Training on real faces. | O28: Recognition accuracy. | P28: Leakage from the generator's training data unresolved. | Q28: synthetic data, scalable identities | R28: Yes | S28: https://github.com/HaiyuWu/vec2face | T28: https://arxiv.org/abs/2409.02979 | U28: Search
A29: 25 | B29: zhao2025 | C29: Visual Content Privacy Protection: A Survey | D29: Ruoyu Zhao, Yushu Zhang, Tao Wang, Wenying Wen, Yong Xiang, Xiaochun Cao | E29: 2025 | F29: ACM Computing Surveys | G29: Journal | H29: Surveys, audits & society | I29: Surveys & society | J29: Survey | K29: Survey | L29: Surveys protection of visual content across the lifecycle, framed by who the adversary is and what they see. | M29: Unifies face, scene and document privacy under one threat taxonomy. | N29: Not applicable. | O29: Not applicable. | P29: Broad rather than deep on faces. | Q29: survey, visual privacy | R29: No | T29: https://arxiv.org/abs/2303.16552 | U29: Search
A30: 26 | B30: papantoniou2024 | C30: Arc2Face: A Foundation Model for ID-Consistent Human Faces | D30: Foivos Paraperas Papantoniou, Alexandros Lattas, Stylianos Moschoglou, Jiankang Deng, Bernhard Kainz, Stefanos Zafeiriou | E30: 2024 | F30: ECCV | G30: Vision | H30: Training-data privacy & synthetic data | I30: Training data & unlearning | J30: WebFace42M (upsampled), FFHQ; LFW, CFP-FP, AgeDB | K30: Stable Diffusion conditioned on ArcFace | L30: Diffusion model conditioned directly on ArcFace embeddings to generate identity-consistent faces at scale. | M30: Enabled high-quality synthetic datasets; also demonstrated how easily an embedding becomes a face, sharpening template-inversion concerns. | N30: Real-data training (and, inversely, template exposure). | O30: Recognition accuracy from synthetic data. | P30: Dual use: a generator for privacy and a tool for inversion. | Q30: foundation model, ArcFace conditioning, synthetic data | R30: Yes | S30: https://github.com/foivospar/Arc2Face | T30: https://arxiv.org/abs/2403.11641 | U30: Search
A31: 27 | B31: zhao2024gridpure | C31: Can Protective Perturbation Safeguard Personal Data from Being Exploited by Stable Diffusion? | D31: Zhengyue Zhao, Jinhao Duan, Kaidi Xu, Chenan Wang, Rui Zhang, Zidong Du, Qi Guo, Xing Hu | E31: 2024 | F31: CVPR | G31: Vision | H31: Attacks & evaluations | I31: Attacks & evaluations | J31: CelebA-HQ, VGGFace2, WikiArt | K31: Stable Diffusion, DreamBooth; DDPM purifier | L31: GrIDPure: grid-based iterative diffusion purification that removes anti-customisation perturbations while preserving image structure. | M31: Anti-DreamBooth, Mist and PhotoGuard protections were largely undone; personalised models trained on purified images worked again. | N31: Photos protected against diffusion personalisation. | O31: Not applicable. | P31: Purification is compute-heavy and can soften fine detail. | Q31: GrIDPure, purification, anti-DreamBooth | R31: Yes | S31: https://github.com/ZhengyueZhao/GrIDPure | T31: https://arxiv.org/abs/2312.00084 | U31: Search
A32: 28 | B32: sun2024 | C32: DiffAM: Diffusion-based Adversarial Makeup Transfer for Facial Privacy Protection | D32: Yuhao Sun, Lingyun Yu, Hongtao Xie, Jiaming Li, Yongdong Zhang | E32: 2024 | F32: CVPR | G32: Vision | H32: Adversarial privacy | I32: Adversarial & unlearnable | J32: CelebA-HQ, LADN, MT | K32: Fine-tuned diffusion with CLIP loss; IR152, IRSE50, FaceNet, MobileFace; commercial APIs | L32: Fine-tuned diffusion model transfers makeup from a reference with a CLIP-based makeup loss and an ensemble attack strategy. | M32: Gain of 12.98% attack success under black-box settings over the previous state of the art, with natural makeup. | N32: Black-box recognisers. | O32: Natural makeup. | P32: Heavy generation cost; static. | Q32: diffusion, makeup, CLIP | R32: Yes | S32: https://github.com/HansSunY/DiffAM | T32: https://arxiv.org/abs/2405.09882 | U32: Search
A33: 29 | B33: cai2024 | C33: Disguise without Disruption: Utility-Preserving Face De-Identification | D33: Zikui Cai, Zhongpai Gao, Benjamin Planche, Meng Zheng, Terrence Chen, M. Salman Asif, Ziyan Wu | E33: 2024 | F33: AAAI | G33: ML | H33: De-identification (generative) | I33: Generative de-identification | J33: Face and clinical benchmarks (see paper) | K33: Generative disguise network constrained by downstream models | L33: Generates a disguised face constrained so that downstream analysis models (e.g., clinical or expression models) produce the same outputs as on the original. | M33: Kept task outputs stable while recognition failed, including on medical images where utility is critical. | N33: Identity recognition on shared analytic data. | O33: Downstream task outputs, by constraint. | P33: Utility tied to chosen tasks; identity leakage through preserved features untested. | Q33: utility, medical, generative | R33: No | T33: https://arxiv.org/abs/2303.13269 | U33: Search
A34: 30 | B34: wang2024facelock | C34: Edit Away and My Face Will Not Stay: Personal Biometric Defense against Malicious Generative Editing | D34: Hanhui Wang, Yihua Zhang, Ruizheng Bai, Yue Zhao, Sijia Liu, Zhengzhong Tu | E34: 2024 | F34: arXiv preprint | G34: Preprint | H34: Unlearnable images & anti-customisation | I34: Adversarial & unlearnable | J34: CelebA-HQ | K34: Stable Diffusion, InstructPix2Pix, ArcFace | L34: FaceLock optimises perturbations so that any diffusion edit of the image destroys the face's biometric identity rather than just image quality. | M34: Edited outputs lost identity by recogniser measures where PhotoGuard-style protection left faces intact. | N34: Malicious editing of personal photos. | O34: Imperceptible noise. | P34: Preprint; purification not fully addressed. | Q34: FaceLock, generative editing, biometric loss | R34: No | T34: https://arxiv.org/abs/2411.16832 | U34: Search
A35: 31 | B35: melzi2024frcsyn | C35: FRCSyn Challenge at WACV 2024: Face Recognition Challenge in the Era of Synthetic Data | D35: Pietro Melzi, Ruben Tolosana, Ruben Vera-Rodriguez, Minchul Kim, Christian Rathgeb, Xiaoming Liu, Ivan DeAndres-Tame, Aythami Morales, Julian Fierrez, Javier Ortega-Garcia, et al. | E35: 2024 | F35: WACV Workshops | G35: Vision | H35: Training-data privacy & synthetic data | I35: Training data & unlearning | J35: DCFace, GANDiffFace (synthetic); CASIA-WebFace; BUPT-BalancedFace, AgeDB, CFP-FP, ROF, IJB-C | K35: Participants' ResNet and ViT recognisers | L35: Community challenge comparing recognisers trained only on synthetic data (DCFace, GANDiffFace) against real-data training, with bias analysis. | M35: Synthetic-only training approached but did not match real data; mixing synthetic and real reduced demographic bias. | N35: Real-data collection for training. | O35: Recognition accuracy. | P35: Fixed generators and protocols. | Q35: challenge, synthetic data, benchmark | R35: No | T35: https://arxiv.org/abs/2311.10476 | U35: Search
A36: 32 | B36: cao2024survey | C36: Face De-identification: State-of-the-art Methods and Comparative Studies | D36: Jingyi Cao, Xiangyi Chen, Bo Liu, Ming Ding, Rong Xie, Li Song, Zhu Li, Wenjun Zhang | E36: 2024 | F36: arXiv preprint (IEEE journal version 2026) | G36: Preprint | H36: Surveys, audits & society | I36: Surveys & society | J36: CelebA-HQ, FFHQ, LFW (comparisons) | K36: Many de-identification methods | L36: Surveys de-identification at pixel, representation and semantic levels and runs quantitative comparisons of leading methods. | M36: GAN and diffusion methods dominate the privacy-utility trade-off; evaluation protocols remain inconsistent. | N36: Not applicable. | O36: Not applicable. | P36: Comparisons on a limited set of benchmarks. | Q36: survey, comparative study, pixel/representation/semantic | R36: No | T36: https://arxiv.org/abs/2411.09863 | U36: Search
A37: 33 | B37: kuang2024 | C37: Facial Identity Anonymization via Intrinsic and Extrinsic Attention Distraction | D37: Zhenzhong Kuang, Xiaochen Yang, Yingjie Shen, Chao Hu, Jun Yu | E37: 2024 | F37: CVPR | G37: Vision | H37: De-identification (generative) | I37: Generative de-identification | J37: CelebA-HQ, FFHQ | K37: Attention-guided generator; ArcFace for evaluation | L37: Distracts a recogniser's attention both inside the face (intrinsic) and via context (extrinsic) while a generator keeps non-identity attributes. | M37: Improved the anonymity-utility balance over GAN baselines on standard benchmarks. | N37: Automated face recognition. | O37: Attributes, background. | P37: Evaluated against a fixed set of recognisers. | Q37: attention, diffusion, attribute preservation | R37: No | T37: https://arxiv.org/abs/2406.17219 | U37: Search
A38: 34 | B38: todt2024 | C38: Fantômas: Understanding Face Anonymization Reversibility | D38: Julian Todt, Simon Hanisch, Thorsten Strufe | E38: 2024 | F38: PoPETs | G38: Security | H38: Attacks & evaluations | I38: Attacks & evaluations | J38: CelebA, LFW | K38: 15 anonymisers; FaceNet/ArcFace matchers | L38: Systematically trains reconstruction and inversion attacks against fifteen face anonymisation methods. | M38: Eleven of fifteen anonymisations were at least partially reversible; visual unrecognisability was a poor proxy for irreversibility. | N38: Attacker with anonymised images and knowledge of the method. | O38: Not applicable. | P38: Attacks assume method knowledge. | Q38: reversibility, anonymisation, evaluation | R38: No | T38: https://arxiv.org/abs/2210.10651 | U38: Search
A39: 35 | B39: zhang2024fmn | C39: Forget-Me-Not: Learning to Forget in Text-to-Image Diffusion Models | D39: Eric Zhang, Kai Wang, Xingqian Xu, Zhangyang Wang, Humphrey Shi | E39: 2024 | F39: CVPR Workshops | G39: Vision | H39: Machine unlearning & auditing | I39: Training data & unlearning | J39: Custom identity and concept prompt sets | K39: Stable Diffusion | L39: Attention re-steering minimises cross-attention to the target concept's tokens so the model forgets identities, objects or styles in seconds. | M39: Forgot celebrity identities and custom concepts with minimal impact on other prompts; released as a lightweight tool. | N39: Generative models reproducing a real person. | O39: Other concepts preserved. | P39: Forgetting can be shallow against paraphrased prompts. | Q39: concept forgetting, attention re-steering, identity | R39: Yes | S39: https://github.com/SHI-Labs/Forget-Me-Not | T39: https://arxiv.org/abs/2303.17591 | U39: Search
A40: 36 | B40: yang2024g2face | C40: G2Face: High-Fidelity Reversible Face Anonymization via Generative and Geometric Priors | D40: Haoxin Yang, Xuemiao Xu, Cheng Xu, Huaidong Zhang, Jing Qin, Yi Wang, Pheng-Ann Heng, Shengfeng He | E40: 2024 | F40: IEEE TIFS | G40: Journal | H40: De-identification (generative) | I40: Generative de-identification | J40: CelebA-HQ, FFHQ, LFW | K40: StyleGAN2, 3DMM; ArcFace | L40: Combines a 3D geometric prior with StyleGAN generative priors and a secret to produce reversible anonymisation at high fidelity. | M40: Better identity removal and recovery quality than RiDDLE-class methods on standard face sets. | N40: Unauthorised recognition of stored or shared images. | O40: Recovery for key holder; pose and expression. | P40: Empirical security of the reversal path. | Q40: reversible, 3D prior, StyleGAN | R40: Yes | S40: https://github.com/Harxis/G2Face | T40: https://arxiv.org/abs/2408.09458 | U40: Search
A41: 37 | B41: hellmann2023 | C41: GANonymization: A GAN-based Face Anonymization Framework for Preserving Emotional Expressions | D41: Fabio Hellmann, Silvan Mertes, Mohamed Benouis, Alexander Hustinx, Tzung-Chien Hsieh, Cristina Conati, Peter Krawitz, Elisabeth André | E41: 2024 | F41: ACM TOMM | G41: Journal | H41: De-identification (generative) | I41: Generative de-identification | J41: CelebA, FFHQ, AffectNet, CK+ | K41: Landmark-to-image GAN | L41: Reduces a face to landmarks and regenerates a new face from them with a GAN, so identity is discarded while expression geometry survives. | M41: Expression recognition on anonymised faces stayed close to the original across several datasets. | N41: Identity recognition in affective-computing datasets. | O41: Emotional expression. | P41: Landmark-only conditioning loses skin, age and gaze cues. | Q41: expression, landmarks, GAN | R41: Yes | S41: https://github.com/hcmlab/GANonymization | T41: https://arxiv.org/abs/2305.02143 | U41: Search
...

Sheet Summary
A1: Entries by year and family
A2: Live COUNTIFS over the "All papers" tab.
A4: Family | B4: Before 2018 | C4: 2018 | D4: 2019 | E4: 2020 | F4: 2021 | G4: 2022 | H4: 2023 | I4: 2024 | J4: 2025 | K4: 2026 | L4: Total
A5: Blur, pixelation & obfuscation | B5: =COUNTIFS('All papers'!$H$5:$H$229,$A5,'All papers'!$E$5:$E$229,"<2018") -> 13 | C5: =COUNTIFS('All papers'!$H$5:$H$229,$A5,'All papers'!$E$5:$E$229,2018) -> 2 | D5: =COUNTIFS('All papers'!$H$5:$H$229,$A5,'All papers'!$E$5:$E$229,2019) -> 0 | E5: =COUNTIFS('All papers'!$H$5:$H$229,$A5,'All papers'!$E$5:$E$229,2020) -> 0 | F5: =COUNTIFS('All papers'!$H$5:$H$229,$A5,'All papers'!$E$5:$E$229,2021) -> 1 | G5: =COUNTIFS('All papers'!$H$5:$H$229,$A5,'All papers'!$E$5:$E$229,2022) -> 0 | H5: =COUNTIFS('All papers'!$H$5:$H$229,$A5,'All papers'!$E$5:$E$229,2023) -> 0 | I5: =COUNTIFS('All papers'!$H$5:$H$229,$A5,'All papers'!$E$5:$E$229,2024) -> 0 | J5: =COUNTIFS('All papers'!$H$5:$H$229,$A5,'All papers'!$E$5:$E$229,2025) -> 0 | K5: =COUNTIFS('All papers'!$H$5:$H$229,$A5,'All papers'!$E$5:$E$229,2026) -> 0 | L5: =SUM(B5:K5) -> 16
A6: Differential privacy | B6: =COUNTIFS('All papers'!$H$5:$H$229,$A6,'All papers'!$E$5:$E$229,"<2018") -> 2 | C6: =COUNTIFS('All papers'!$H$5:$H$229,$A6,'All papers'!$E$5:$E$229,2018) -> 2 | D6: =COUNTIFS('All papers'!$H$5:$H$229,$A6,'All papers'!$E$5:$E$229,2019) -> 3 | E6: =COUNTIFS('All papers'!$H$5:$H$229,$A6,'All papers'!$E$5:$E$229,2020) -> 1 | F6: =COUNTIFS('All papers'!$H$5:$H$229,$A6,'All papers'!$E$5:$E$229,2021) -> 2 | G6: =COUNTIFS('All papers'!$H$5:$H$229,$A6,'All papers'!$E$5:$E$229,2022) -> 2 | H6: =COUNTIFS('All papers'!$H$5:$H$229,$A6,'All papers'!$E$5:$E$229,2023) -> 2 | I6: =COUNTIFS('All papers'!$H$5:$H$229,$A6,'All papers'!$E$5:$E$229,2024) -> 0 | J6: =COUNTIFS('All papers'!$H$5:$H$229,$A6,'All papers'!$E$5:$E$229,2025) -> 0 | K6: =COUNTIFS('All papers'!$H$5:$H$229,$A6,'All papers'!$E$5:$E$229,2026) -> 0 | L6: =SUM(B6:K6) -> 14
A7: De-identification (generative) | B7: =COUNTIFS('All papers'!$H$5:$H$229,$A7,'All papers'!$E$5:$E$229,"<2018") -> 1 | C7: =COUNTIFS('All papers'!$H$5:$H$229,$A7,'All papers'!$E$5:$E$229,2018) -> 3 | D7: =COUNTIFS('All papers'!$H$5:$H$229,$A7,'All papers'!$E$5:$E$229,2019) -> 3 | E7: =COUNTIFS('All papers'!$H$5:$H$229,$A7,'All papers'!$E$5:$E$229,2020) -> 2 | F7: =COUNTIFS('All papers'!$H$5:$H$229,$A7,'All papers'!$E$5:$E$229,2021) -> 2 | G7: =COUNTIFS('All papers'!$H$5:$H$229,$A7,'All papers'!$E$5:$E$229,2022) -> 0 | H7: =COUNTIFS('All papers'!$H$5:$H$229,$A7,'All papers'!$E$5:$E$229,2023) -> 7 | I7: =COUNTIFS('All papers'!$H$5:$H$229,$A7,'All papers'!$E$5:$E$229,2024) -> 6 | J7: =COUNTIFS('All papers'!$H$5:$H$229,$A7,'All papers'!$E$5:$E$229,2025) -> 4 | K7: =COUNTIFS('All papers'!$H$5:$H$229,$A7,'All papers'!$E$5:$E$229,2026) -> 0 | L7: =SUM(B7:K7) -> 28
A8: Adversarial privacy | B8: =COUNTIFS('All papers'!$H$5:$H$229,$A8,'All papers'!$E$5:$E$229,"<2018") -> 4 | C8: =COUNTIFS('All papers'!$H$5:$H$229,$A8,'All papers'!$E$5:$E$229,2018) -> 1 | D8: =COUNTIFS('All papers'!$H$5:$H$229,$A8,'All papers'!$E$5:$E$229,2019) -> 1 | E8: =COUNTIFS('All papers'!$H$5:$H$229,$A8,'All papers'!$E$5:$E$229,2020) -> 3 | F8: =COUNTIFS('All papers'!$H$5:$H$229,$A8,'All papers'!$E$5:$E$229,2021) -> 7 | G8: =COUNTIFS('All papers'!$H$5:$H$229,$A8,'All papers'!$E$5:$E$229,2022) -> 5 | H8: =COUNTIFS('All papers'!$H$5:$H$229,$A8,'All papers'!$E$5:$E$229,2023) -> 1 | I8: =COUNTIFS('All papers'!$H$5:$H$229,$A8,'All papers'!$E$5:$E$229,2024) -> 2 | J8: =COUNTIFS('All papers'!$H$5:$H$229,$A8,'All papers'!$E$5:$E$229,2025) -> 5 | K8: =COUNTIFS('All papers'!$H$5:$H$229,$A8,'All papers'!$E$5:$E$229,2026) -> 1 | L8: =SUM(B8:K8) -> 30
A9: Unlearnable images & anti-customisation | B9: =COUNTIFS('All papers'!$H$5:$H$229,$A9,'All papers'!$E$5:$E$229,"<2018") -> 0 | C9: =COUNTIFS('All papers'!$H$5:$H$229,$A9,'All papers'!$E$5:$E$229,2018) -> 0 | D9: =COUNTIFS('All papers'!$H$5:$H$229,$A9,'All papers'!$E$5:$E$229,2019) -> 0 | E9: =COUNTIFS('All papers'!$H$5:$H$229,$A9,'All papers'!$E$5:$E$229,2020) -> 0 | F9: =COUNTIFS('All papers'!$H$5:$H$229,$A9,'All papers'!$E$5:$E$229,2021) -> 2 | G9: =COUNTIFS('All papers'!$H$5:$H$229,$A9,'All papers'!$E$5:$E$229,2022) -> 3 | H9: =COUNTIFS('All papers'!$H$5:$H$229,$A9,'All papers'!$E$5:$E$229,2023) -> 8 | I9: =COUNTIFS('All papers'!$H$5:$H$229,$A9,'All papers'!$E$5:$E$229,2024) -> 5 | J9: =COUNTIFS('All papers'!$H$5:$H$229,$A9,'All papers'!$E$5:$E$229,2025) -> 1 | K9: =COUNTIFS('All papers'!$H$5:$H$229,$A9,'All papers'!$E$5:$E$229,2026) -> 0 | L9: =SUM(B9:K9) -> 19
A10: Identity protection: templates & encrypted matching | B10: =COUNTIFS('All papers'!$H$5:$H$229,$A10,'All papers'!$E$5:$E$229,"<2018") -> 9 | C10: =COUNTIFS('All papers'!$H$5:$H$229,$A10,'All papers'!$E$5:$E$229,2018) -> 3 | D10: =COUNTIFS('All papers'!$H$5:$H$229,$A10,'All papers'!$E$5:$E$229,2019) -> 0 | E10: =COUNTIFS('All papers'!$H$5:$H$229,$A10,'All papers'!$E$5:$E$229,2020) -> 1 | F10: =COUNTIFS('All papers'!$H$5:$H$229,$A10,'All papers'!$E$5:$E$229,2021) -> 1 | G10: =COUNTIFS('All papers'!$H$5:$H$229,$A10,'All papers'!$E$5:$E$229,2022) -> 8 | H10: =COUNTIFS('All papers'!$H$5:$H$229,$A10,'All papers'!$E$5:$E$229,2023) -> 2 | I10: =COUNTIFS('All papers'!$H$5:$H$229,$A10,'All papers'!$E$5:$E$229,2024) -> 1 | J10: =COUNTIFS('All papers'!$H$5:$H$229,$A10,'All papers'!$E$5:$E$229,2025) -> 0 | K10: =COUNTIFS('All papers'!$H$5:$H$229,$A10,'All papers'!$E$5:$E$229,2026) -> 0 | L10: =SUM(B10:K10) -> 25
A11: Soft-biometric privacy | B11: =COUNTIFS('All papers'!$H$5:$H$229,$A11,'All papers'!$E$5:$E$229,"<2018") -> 1 | C11: =COUNTIFS('All papers'!$H$5:$H$229,$A11,'All papers'!$E$5:$E$229,2018) -> 1 | D11: =COUNTIFS('All papers'!$H$5:$H$229,$A11,'All papers'!$E$5:$E$229,2019) -> 2 | E11: =COUNTIFS('All papers'!$H$5:$H$229,$A11,'All papers'!$E$5:$E$229,2020) -> 5 | F11: =COUNTIFS('All papers'!$H$5:$H$229,$A11,'All papers'!$E$5:$E$229,2021) -> 2 | G11: =COUNTIFS('All papers'!$H$5:$H$229,$A11,'All papers'!$E$5:$E$229,2022) -> 0 | H11: =COUNTIFS('All papers'!$H$5:$H$229,$A11,'All papers'!$E$5:$E$229,2023) -> 1 | I11: =COUNTIFS('All papers'!$H$5:$H$229,$A11,'All papers'!$E$5:$E$229,2024) -> 0 | J11: =COUNTIFS('All papers'!$H$5:$H$229,$A11,'All papers'!$E$5:$E$229,2025) -> 0 | K11: =COUNTIFS('All papers'!$H$5:$H$229,$A11,'All papers'!$E$5:$E$229,2026) -> 0 | L11: =SUM(B11:K11) -> 12
A12: Training-data privacy & synthetic data | B12: =COUNTIFS('All papers'!$H$5:$H$229,$A12,'All papers'!$E$5:$E$229,"<2018") -> 1 | C12: =COUNTIFS('All papers'!$H$5:$H$229,$A12,'All papers'!$E$5:$E$229,2018) -> 0 | D12: =COUNTIFS('All papers'!$H$5:$H$229,$A12,'All papers'!$E$5:$E$229,2019) -> 0 | E12: =COUNTIFS('All papers'!$H$5:$H$229,$A12,'All papers'!$E$5:$E$229,2020) -> 1 | F12: =COUNTIFS('All papers'!$H$5:$H$229,$A12,'All papers'!$E$5:$E$229,2021) -> 3 | G12: =COUNTIFS('All papers'!$H$5:$H$229,$A12,'All papers'!$E$5:$E$229,2022) -> 3 | H12: =COUNTIFS('All papers'!$H$5:$H$229,$A12,'All papers'!$E$5:$E$229,2023) -> 4 | I12: =COUNTIFS('All papers'!$H$5:$H$229,$A12,'All papers'!$E$5:$E$229,2024) -> 2 | J12: =COUNTIFS('All papers'!$H$5:$H$229,$A12,'All papers'!$E$5:$E$229,2025) -> 1 | K12: =COUNTIFS('All papers'!$H$5:$H$229,$A12,'All papers'!$E$5:$E$229,2026) -> 0 | L12: =SUM(B12:K12) -> 15
A13: Machine unlearning & auditing | B13: =COUNTIFS('All papers'!$H$5:$H$229,$A13,'All papers'!$E$5:$E$229,"<2018") -> 2 | C13: =COUNTIFS('All papers'!$H$5:$H$229,$A13,'All papers'!$E$5:$E$229,2018) -> 0 | D13: =COUNTIFS('All papers'!$H$5:$H$229,$A13,'All papers'!$E$5:$E$229,2019) -> 0 | E13: =COUNTIFS('All papers'!$H$5:$H$229,$A13,'All papers'!$E$5:$E$229,2020) -> 2 | F13: =COUNTIFS('All papers'!$H$5:$H$229,$A13,'All papers'!$E$5:$E$229,2021) -> 1 | G13: =COUNTIFS('All papers'!$H$5:$H$229,$A13,'All papers'!$E$5:$E$229,2022) -> 1 | H13: =COUNTIFS('All papers'!$H$5:$H$229,$A13,'All papers'!$E$5:$E$229,2023) -> 8 | I13: =COUNTIFS('All papers'!$H$5:$H$229,$A13,'All papers'!$E$5:$E$229,2024) -> 4 | J13: =COUNTIFS('All papers'!$H$5:$H$229,$A13,'All papers'!$E$5:$E$229,2025) -> 0 | K13: =COUNTIFS('All papers'!$H$5:$H$229,$A13,'All papers'!$E$5:$E$229,2026) -> 0 | L13: =SUM(B13:K13) -> 18
A14: Attacks & evaluations | B14: =COUNTIFS('All papers'!$H$5:$H$229,$A14,'All papers'!$E$5:$E$229,"<2018") -> 3 | C14: =COUNTIFS('All papers'!$H$5:$H$229,$A14,'All papers'!$E$5:$E$229,2018) -> 0 | D14: =COUNTIFS('All papers'!$H$5:$H$229,$A14,'All papers'!$E$5:$E$229,2019) -> 1 | E14: =COUNTIFS('All papers'!$H$5:$H$229,$A14,'All papers'!$E$5:$E$229,2020) -> 1 | F14: =COUNTIFS('All papers'!$H$5:$H$229,$A14,'All papers'!$E$5:$E$229,2021) -> 2 | G14: =COUNTIFS('All papers'!$H$5:$H$229,$A14,'All papers'!$E$5:$E$229,2022) -> 2 | H14: =COUNTIFS('All papers'!$H$5:$H$229,$A14,'All papers'!$E$5:$E$229,2023) -> 5 | I14: =COUNTIFS('All papers'!$H$5:$H$229,$A14,'All papers'!$E$5:$E$229,2024) -> 4 | J14: =COUNTIFS('All papers'!$H$5:$H$229,$A14,'All papers'!$E$5:$E$229,2025) -> 4 | K14: =COUNTIFS('All papers'!$H$5:$H$229,$A14,'All papers'!$E$5:$E$229,2026) -> 3 | L14: =SUM(B14:K14) -> 25
A15: Surveys, audits & society | B15: =COUNTIFS('All papers'!$H$5:$H$229,$A15,'All papers'!$E$5:$E$229,"<2018") -> 3 | C15: =COUNTIFS('All papers'!$H$5:$H$229,$A15,'All papers'!$E$5:$E$229,2018) -> 1 | D15: =COUNTIFS('All papers'!$H$5:$H$229,$A15,'All papers'!$E$5:$E$229,2019) -> 2 | E15: =COUNTIFS('All papers'!$H$5:$H$229,$A15,'All papers'!$E$5:$E$229,2020) -> 3 | F15: =COUNTIFS('All papers'!$H$5:$H$229,$A15,'All papers'!$E$5:$E$229,2021) -> 4 | G15: =COUNTIFS('All papers'!$H$5:$H$229,$A15,'All papers'!$E$5:$E$229,2022) -> 0 | H15: =COUNTIFS('All papers'!$H$5:$H$229,$A15,'All papers'!$E$5:$E$229,2023) -> 3 | I15: =COUNTIFS('All papers'!$H$5:$H$229,$A15,'All papers'!$E$5:$E$229,2024) -> 1 | J15: =COUNTIFS('All papers'!$H$5:$H$229,$A15,'All papers'!$E$5:$E$229,2025) -> 2 | K15: =COUNTIFS('All papers'!$H$5:$H$229,$A15,'All papers'!$E$5:$E$229,2026) -> 4 | L15: =SUM(B15:K15) -> 23
A16: Total | B16: =SUM(B5:B15) -> 39 | C16: =SUM(C5:C15) -> 13 | D16: =SUM(D5:D15) -> 12 | E16: =SUM(E5:E15) -> 19 | F16: =SUM(F5:F15) -> 27 | G16: =SUM(G5:G15) -> 24 | H16: =SUM(H5:H15) -> 41 | I16: =SUM(I5:I15) -> 25 | ... L16: =SUM(L5:L15) -> 225
A19: Other counts
A20: Entries with public code | B20: =COUNTIF('All papers'!$R$5:$R$229,"Yes") -> 77
A21: Entries from 2018 onward | B21: =COUNTIF('All papers'!$E$5:$E$229,">=2018") -> 186
A22: Preprints or under review | B22: =COUNTIF('All papers'!$G$5:$G$229,"Preprint") -> 24
A23: Grey literature (Other) | B23: =COUNTIF('All papers'!$G$5:$G$229,"Other") -> 14
A24: All entries | B24: =COUNTA('All papers'!$H$5:$H$229) -> 225

Sheet Before 2018
A1: Before 2018
A2: 39 entries before 2018: the foundations.
A4: # | B4: ID | C4: Paper title | D4: Authors | E4: Year | F4: Venue | G4: Venue type | H4: Family | I4: Chart group | J4: Datasets | K4: Models / backbones | L4: Approach | M4: Key findings | N4: Threat model / protects against | O4: Utility preserved | P4: Limitations & known attacks | Q4: Tags | R4: Code available | S4: GitHub / code link | T4: Paper link | U4: Google Scholar
A5: 1 | B5: oh2017 | C5: Adversarial Image Perturbation for Privacy Protection: A Game Theory Perspective | D5: Seong Joon Oh, Mario Fritz, Bernt Schiele | E5: 2017 | F5: ICCV | G5: Vision | H5: Adversarial privacy | I5: Adversarial & unlearnable | J5: PIPA | K5: ResNet person recogniser (head and body cues) | L5: Models user and recogniser as players: the user perturbs, the recogniser may adapt (e.g., train on perturbed data). Studies equilibria. | M5: Showed that a recogniser who knows the perturbation strategy recovers much accuracy; users must randomise to keep any advantage. An early warning of the arms race. | N5: Adaptive person recognisers on social media. | O5: Perturbations kept small. | P5: Analysis limited to 2017 architectures. | Q5: game theory, perturbation, recogniser adaptation | R5: No | T5: https://arxiv.org/abs/1703.09471 | U5: Search
A6: 2 | B6: brkic2017 | C6: I Know That Person: Generative Full Body and Face De-identification of People in Images | D6: Karla Brkić, Ivan Sikirić, Tomislav Hrkać, Zoran Kalafatić | E6: 2017 | F6: CVPR Workshops | G6: Vision | H6: De-identification (generative) | I6: Generative de-identification | J6: Own surveillance-style images; ClothingAttributes | K6: Segmentation + generative replacement | L6: Segments people and replaces face and body with generated appearance, keeping pose. | M6: Early demonstration that generative replacement can de-identify the whole person, not just the face. | N6: Recognition by face and by clothing or body. | O6: Pose and scene. | P6: Low resolution; identity leakage through unreplaced cues. | Q6: GAN, full body, de-identification | R6: No | T6: https://doi.org/10.1109/CVPRW.2017.173 | U6: Search
A7: 3 | B7: shokri2017 | C7: Membership Inference Attacks Against Machine Learning Models | D7: Reza Shokri, Marco Stronati, Congzheng Song, Vitaly Shmatikov | E7: 2017 | F7: IEEE Symposium on Security and Privacy | G7: Security | H7: Machine unlearning & auditing | I7: Training data & unlearning | J7: CIFAR, Purchase, Texas hospital, MNIST, UCI Adult | K7: Google Prediction API, Amazon ML, CNNs | L7: Shadow models trained to mimic a target let an attacker tell whether a record was in the target's training set from its outputs. | M7: Black-box membership inference against commercial ML-as-a-service models; overfitting drives leakage. | N7: Proving a person's data was used to train a model. | O7: Not applicable. | P7: Later work shows weaker attacks on well-generalised models; face-specific variants followed. | Q7: membership inference, auditing, foundational | R7: No | T7: https://arxiv.org/abs/1610.05820 | U7: Search
A8: 4 | B8: ryoo2017 | C8: Privacy-Preserving Human Activity Recognition from Extreme Low Resolution | D8: Michael S. Ryoo, Brandon Rothrock, Charles Fleming, Hyun Jong Yang | E8: 2017 | F8: AAAI | G8: ML | H8: Blur, pixelation & obfuscation | I8: Obfuscation & differential privacy | J8: HMDB, DogCentric at 16×12 | K8: Two-stream CNN with inverse super-resolution | L8: Recognises human activities from 16×12 pixel video using inverse super-resolution to learn from multiple low-resolution transforms. | M8: Activity recognition stayed useful at resolutions where faces are unrecognisable, motivating low-resolution cameras as privacy by design. | N8: Identification from in-home or workplace cameras. | O8: Activity recognition. | P8: Fine-grained tasks impossible; gait and body shape can still identify. | Q8: extreme low resolution, activity recognition, inverse super-resolution | R8: No | T8: https://ojs.aaai.org/index.php/AAAI/article/view/11233 | U8: Search
A9: 5 | B9: mirjalili2017 | C9: Soft Biometric Privacy: Retaining Biometric Utility of Face Images While Perturbing Gender | D9: Vahid Mirjalili, Arun Ross | E9: 2017 | F9: IJCB | G9: Biometrics | H9: Soft-biometric privacy | I9: Soft-biometric privacy | J9: MUCT, LFW, CelebA | K9: Commercial face matcher; IntraFace gender classifier | L9: Perturbs face images so gender classifiers fail while a face matcher still verifies identity. | M9: Gender prediction dropped toward chance with small loss in matching accuracy. | N9: Automated attribute inference from stored face images. | O9: Identity matching. | P9: Classifier-specific perturbations; later shown recoverable. | Q9: gender, perturbation, matching utility | R9: No | T9: https://doi.org/10.1109/BTAS.2017.8272743 | U9: Search
A10: 6 | B10: sharif2016 | C10: Accessorize to a Crime: Real and Stealthy Attacks on State-of-the-Art Face Recognition | D10: Mahmood Sharif, Sruti Bhagavatula, Lujo Bauer, Michael K. Reiter | E10: 2016 | F10: ACM CCS | G10: Security | H10: Adversarial privacy | I10: Adversarial & unlearnable | J10: PubFig; own photographs | K10: VGG-Face based DNNs | L10: Prints adversarial patterns onto eyeglass frames so a wearer either evades recognition (dodging) or is recognised as a chosen target (impersonation). | M10: Physically realised attacks on a deep recogniser; high dodging success and impersonation success above 80% for some target pairs. | N10: White-box and, in follow-ups, black-box deep face recognition. | O10: Wearer looks like a person in glasses. | P10: Needed model access originally; patterns are visibly odd; later systems retrained. | Q10: physical, eyeglasses, dodging, impersonation | R10: No | T10: https://doi.org/10.1145/2976749.2978392 | U10: Search
A11: 7 | B11: ribaric2016 | C11: De-identification for Privacy Protection in Multimedia Content: A Survey | D11: Slobodan Ribaric, Aladdin Ariyaeeinia, Nikola Pavesic | E11: 2016 | F11: Signal Processing: Image Communication | G11: Journal | H11: Surveys, audits & society | I11: Surveys & society | J11: Survey (many) | K11: Survey | L11: Survey covering de-identification of face, gait, voice, text and soft biometrics across images, video and audio. | M11: Framed de-identification as a multimodal problem and set out evaluation criteria (naturalness, reversibility, utility) later surveys reuse. | N11: Identification from any biometric or non-biometric identifier in media. | O11: Discussed as a design criterion. | P11: Written just before deep generative de-identification took over. | Q11: survey, de-identification, multimodal | R11: No | T11: https://doi.org/10.1016/j.image.2016.05.020 | U11: Search
A12: 8 | B12: abadi2016 | C12: Deep Learning with Differential Privacy | D12: Martín Abadi, Andy Chu, Ian Goodfellow, H. Brendan McMahan, Ilya Mironov, Kunal Talwar, Li Zhang | E12: 2016 | F12: ACM CCS | G12: Security | H12: Differential privacy | I12: Obfuscation & differential privacy | J12: MNIST, CIFAR-10 | K12: CNNs | L12: DP-SGD: clip per-example gradients and add Gaussian noise, with a moments accountant to track the privacy budget. | M12: Trained image classifiers with formal DP at modest accuracy cost; the standard for DP training of face and other models. | N12: Membership and reconstruction attacks on trained models. | O12: Model accuracy (reduced). | P12: Accuracy gap widens on large models and fine-grained tasks such as face recognition. | Q12: DP-SGD, moments accountant, training | R12: Yes | S12: https://github.com/tensorflow/privacy | T12: https://arxiv.org/abs/1607.00133 | U12: Search
A13: 9 | B13: pandey2016 | C13: Deep Secure Encoding for Face Template Protection | D13: Rohit Kumar Pandey, Yingbo Zhou, Bhargava Urala Kota, Venu Govindaraju | E13: 2016 | F13: CVPR Workshops | G13: Vision | H13: Identity protection: templates & encrypted matching | I13: Template protection | J13: CMU-PIE, Extended Yale B, Multi-PIE | K13: CNN + SHA-512 | L13: Trains a CNN to map a user's face images to a random binary code that is then cryptographically hashed, so only the hash is stored. | M13: High matching accuracy with a stored template that is a one-way hash. | N13: Template database theft. | O13: Verification accuracy. | P13: Per-user training; small closed datasets. | Q13: binary codes, hashing, CNN | R13: No | T13: https://doi.org/10.1109/CVPRW.2016.17 | U13: Search
A14: 10 | B14: mcpherson2016 | C14: Defeating Image Obfuscation with Deep Learning | D14: Richard McPherson, Reza Shokri, Vitaly Shmatikov | E14: 2016 | F14: arXiv preprint | G14: Preprint | H14: Attacks & evaluations | I14: Attacks & evaluations | J14: MNIST, CIFAR-10, AT&T faces, FaceScrub | K14: CNN classifiers trained on obfuscated data | L14: Trains recognisers directly on obfuscated images (mosaicing, YouTube-style blur, P3 encryption) to identify faces, digits and objects. | M14: Identification far above chance on all three obfuscations, including heavy pixelation; showed obfuscation designed for human eyes does not stop machines. | N14: Anyone with obfuscated images and a labelled reference set. | O14: Not applicable. | P14: Closed-set recognition; still the standard citation against blur and pixelation. | Q14: pixelation, blur, P3, recognition | R14: No | T14: https://arxiv.org/abs/1609.00408 | U14: Search
A15: 11 | B15: oh2016 | C15: Faceless Person Recognition: Privacy Implications in Social Media | D15: Seong Joon Oh, Rodrigo Benenson, Mario Fritz, Bernt Schiele | E15: 2016 | F15: ECCV | G15: Vision | H15: Attacks & evaluations | I15: Attacks & evaluations | J15: PIPA | K15: AlexNet-based person recogniser | L15: Recognises people in social-media photos from body, clothing and scene even when faces are blurred or blacked out. | M15: Substantial recognition with only a handful of tagged examples and no visible face; obfuscating the face alone protects less than assumed. | N15: Recognition from non-face cues. | O15: Not applicable. | P15: Studied a single album domain; motivated full-body anonymisation. | Q15: person recognition, context, blur | R15: No | T15: https://arxiv.org/abs/1607.08438 | U15: Search
A16: 12 | B16: zhmoginov2016 | C16: Inverting Face Embeddings with Convolutional Neural Networks | D16: Andrey Zhmoginov, Mark Sandler | E16: 2016 | F16: arXiv preprint | G16: Preprint | H16: Attacks & evaluations | I16: Attacks & evaluations | J16: LFW-scale face sets | K16: FaceNet embeddings; CNN inverter | L16: Trains a network to reconstruct a face image from a FaceNet embedding. | M16: Recognisable reconstructions from 128 numbers, the first public demonstration that deep templates leak appearance. | N16: Attacker holding stolen embeddings. | O16: Not applicable. | P16: Low resolution; white-box embedding model. | Q16: template inversion, FaceNet | R16: No | T16: https://arxiv.org/abs/1606.04189 | U16: Search
A17: 13 | B17: guo2016 | C17: MS-Celeb-1M: A Dataset and Benchmark for Large-Scale Face Recognition | D17: Yandong Guo, Lei Zhang, Yuxiao Hu, Xiaodong He, Jianfeng Gao | E17: 2016 | F17: ECCV | G17: Vision | H17: Training-data privacy & synthetic data | I17: Training data & unlearning | J17: MS-Celeb-1M | K17: Benchmark for deep recognisers | L17: Ten million web-scraped images of about 100,000 celebrities as a training benchmark. | M17: Powered a generation of recognisers; withdrawn by Microsoft in 2019 after the Exposing.ai investigation showed it included non-celebrities and had been used by surveillance vendors. Copies still circulate as MS1M variants. | N17: Not a protection paper: the canonical example of the consent problem. | O17: Not applicable. | P17: Noisy labels; withdrawn. | Q17: dataset, scraping, withdrawn | R17: No | T17: https://arxiv.org/abs/1607.08221 | U17: Search
A18: 14 | B18: garvie2016 | C18: The Perpetual Line-Up: Unregulated Police Face Recognition in America | D18: Clare Garvie, Alvaro Bedoya, Jonathan Frankle | E18: 2016 | F18: Georgetown Law Center on Privacy & Technology | G18: Other | H18: Surveys, audits & society | I18: Surveys & society | J18: Records from 100+ US agencies | K18: None | L18: Records requests to over 100 US police agencies on face recognition use, databases and safeguards. | M18: Estimated half of American adults were in a law-enforcement face network; found almost no accuracy testing, bias audits or legal limits. | N18: State use of driver's licence photos for identification. | O18: Not applicable. | P18: US only; snapshot of 2016. | Q18: policy, police, audit | R18: No | T18: https://www.perpetuallineup.org | U18: Search
